Workbook

Sheet ملخص العرض
A1: ملخص العرض المالي
A3: المكوّن | B3: المبلغ (ر.س) | C3: من سعر العرض
A4: التكلفة المباشرة | B4: =SUM('ملخص البنود'!C5:C22) -> 830892.6 | C4: =IF($B$13=0,0,B4/$B$13) -> 0.70544617
A5: مصاريف المشروع غير المباشرة | B5: ='مصاريف المشروع'!$F$11 -> 112500 | C5: =IF($B$13=0,0,B5/$B$13) -> 0.095514985
A6: تكلفة المشروع | B6: =B4+B5 -> 943392.6 | C6: =IF($B$13=0,0,B6/$B$13) -> 0.80096115
A7: المصاريف العامة للشركة | B7: =B6*المدخلات!$B$18 -> 47169.63 | C7: =IF($B$13=0,0,B7/$B$13) -> 0.040048058
A8: تكلفة التمويل | B8: =B6*المدخلات!$B$19 -> 23584.815 | C8: =IF($B$13=0,0,B8/$B$13) -> 0.020024029
A9: الضمانات البنكية والتأمين | B9: =B6*المدخلات!$B$20 -> 9433.926 | C9: =IF($B$13=0,0,B9/$B$13) -> 0.0080096115
A10: المخاطر والطوارئ | B10: =B6*المدخلات!$B$21 -> 47169.63 | C10: =IF($B$13=0,0,B10/$B$13) -> 0.040048058
A11: إجمالي التكلفة | B11: =SUM(B6:B10) -> 1070750.6 | C11: =IF($B$13=0,0,B11/$B$13) -> 0.90909091
A12: الربح | B12: =B11*المدخلات!$B$22 -> 107075.06 | C12: =IF($B$13=0,0,B12/$B$13) -> 0.090909091
A13: سعر العرض قبل الضريبة (محسوب) | B13: =B11+B12 -> 1177825.7 | C13: =IF($B$13=0,0,B13/$B$13) -> 1
A14: معامل التحميل على التكلفة المباشرة | B14: =B13/B4 -> 1.4175426
A15: مجموع جدول الكميات المسعّر (المعتمد في العرض) | B15: ='ملخص البنود'!I23 -> 1177825.7
A16: ضريبة القيمة المضافة | B16: =B15*المدخلات!$B$23 -> 176673.85
A17: الإجمالي شامل الضريبة | B17: =B15+B16 -> 1354499.5
A19: سعر العرض السابق قبل الضريبة (21/10/2026) | B19: 1299139.1
A20: الفرق عن العرض السابق | B20: =B15-B19 -> -121313.48
A21: نسبة الفرق | B21: =IF(B19=0,0,B20/B19) -> -0.093379897
A23: تكوين التكلفة المباشرة حسب مستوى الثقة
A24: مستوى الثقة | B24: المبلغ (ر.س) | C24: من التكلفة المباشرة
A25: مصدر سعودي | B25: =SUMIF('تكسير البنود'!$L$4:$L$241,A25,'تكسير البنود'!$J$4:$J$241) -> 17370.33 | C25: =IF($B$4=0,0,B25/$B$4) -> 0.020905626
A26: مصدر دولي + استيراد | B26: =SUMIF('تكسير البنود'!$L$4:$L$241,A26,'تكسير البنود'!$J$4:$J$241) -> 134401.89 | C26: =IF($B$4=0,0,B26/$B$4) -> 0.16175603
A27: تقدير بين مصادر | B27: =SUMIF('تكسير البنود'!$L$4:$L$241,A27,'تكسير البنود'!$J$4:$J$241) -> 139742.25 | C27: =IF($B$4=0,0,B27/$B$4) -> 0.16818329
A28: افتراض — يلزم عرض سعر | B28: =SUMIF('تكسير البنود'!$L$4:$L$241,A28,'تكسير البنود'!$J$4:$J$241) -> 539378.12 | C28: =IF($B$4=0,0,B28/$B$4) -> 0.64915505
A30: تكوين التكلفة المباشرة حسب النوع
A31: النوع | B31: المبلغ (ر.س) | C31: من التكلفة المباشرة
A32: مواد/معدات | B32: =SUMIF('تكسير البنود'!$K$4:$K$241,A32,'تكسير البنود'!$J$4:$J$241) -> 635152.6 | C32: =IF($B$4=0,0,B32/$B$4) -> 0.76442202
A33: عمالة | B33: =SUMIF('تكسير البنود'!$K$4:$K$241,A33,'تكسير البنود'!$J$4:$J$241) -> 118040 | C33: =IF($B$4=0,0,B33/$B$4) -> 0.14206409
A34: مقاول باطن/خدمة | B34: =SUMIF('تكسير البنود'!$K$4:$K$241,A34,'تكسير البنود'!$J$4:$J$241) -> 77700 | C34: =IF($B$4=0,0,B34/$B$4) -> 0.093513891
A36: تحقق: مجموع التكوين يساوي التكلفة المباشرة | B36: =ROUND(SUM(B25:B28)-B4,2) -> 0

Sheet ملخص البنود
A1: ملخص البنود وجدول الكميات المسعّر
A2: التكلفة المباشرة من ورقة التكسير، والسعر = التكلفة × معامل التحميل (توزيع متوازن). الأسعار قبل الضريبة.
A4: البند | B4: الوصف | C4: التكلفة المباشرة (ر.س) | D4: تقدير التصميم R03 (ر.س) | E4: الفرق (ر.س) | F4: الفرق % | G4: منها افتراضات (ر.س) | H4: نسبة الافتراضات | I4: سعر البند في العرض (ر.س)
A5: 01 | B5: شاسيه سيمي تريلر منخفض 12 م | C5: =SUMIF('تكسير البنود'!$A$4:$A$241,A5,'تكسير البنود'!$J$4:$J$241) -> 96996.25 | D5: 92000 | E5: =C5-D5 -> 4996.25 | F5: =IF(D5=0,0,E5/D5) -> 0.054307065 | G5: =SUMIFS('تكسير البنود'!$J$4:$J$241,'تكسير البنود'!$A$4:$A$241,A5,'تكسير البنود'!$L$4:$L$241,"افتراض — يلزم عرض سعر") -> 90958.75 | H5: =IF(C5=0,0,G5/C5) -> 0.93775533 | I5: =ROUND(C5*'ملخص العرض'!$B$14,2) -> 137496.32
A6: 02 | B6: هيكل الصندوق والعزل والأرضية | C6: =SUMIF('تكسير البنود'!$A$4:$A$241,A6,'تكسير البنود'!$J$4:$J$241) -> 95920 | D6: 118000 | E6: =C6-D6 -> -22080 | F6: =IF(D6=0,0,E6/D6) -> -0.18711864 | G6: =SUMIFS('تكسير البنود'!$J$4:$J$241,'تكسير البنود'!$A$4:$A$241,A6,'تكسير البنود'!$L$4:$L$241,"افتراض — يلزم عرض سعر") -> 80400 | H6: =IF(C6=0,0,G6/C6) -> 0.8381985 | I6: =ROUND(C6*'ملخص العرض'!$B$14,2) -> 135970.69
A7: 03 | B7: الأبواب والنوافذ | C7: =SUMIF('تكسير البنود'!$A$4:$A$241,A7,'تكسير البنود'!$J$4:$J$241) -> 39400 | D7: 34000 | E7: =C7-D7 -> 5400 | F7: =IF(D7=0,0,E7/D7) -> 0.15882353 | G7: =SUMIFS('تكسير البنود'!$J$4:$J$241,'تكسير البنود'!$A$4:$A$241,A7,'تكسير البنود'!$L$4:$L$241,"افتراض — يلزم عرض سعر") -> 39400 | H7: =IF(C7=0,0,G7/C7) -> 1 | I7: =ROUND(C7*'ملخص العرض'!$B$14,2) -> 55851.18
A8: 04 | B8: مصعد الكراسي والسلالم | C8: =SUMIF('تكسير البنود'!$A$4:$A$241,A8,'تكسير البنود'!$J$4:$J$241) -> 55061.25 | D8: 48000 | E8: =C8-D8 -> 7061.25 | F8: =IF(D8=0,0,E8/D8) -> 0.14710937 | G8: =SUMIFS('تكسير البنود'!$J$4:$J$241,'تكسير البنود'!$A$4:$A$241,A8,'تكسير البنود'!$L$4:$L$241,"افتراض — يلزم عرض سعر") -> 9780 | H8: =IF(C8=0,0,G8/C8) -> 0.17762038 | I8: =ROUND(C8*'ملخص العرض'!$B$14,2) -> 78051.67
A9: 05 | B9: التشطيبات الداخلية والأثاث | C9: =SUMIF('تكسير البنود'!$A$4:$A$241,A9,'تكسير البنود'!$J$4:$J$241) -> 52030 | D9: 58000 | E9: =C9-D9 -> -5970 | F9: =IF(D9=0,0,E9/D9) -> -0.10293103 | G9: =SUMIFS('تكسير البنود'!$J$4:$J$241,'تكسير البنود'!$A$4:$A$241,A9,'تكسير البنود'!$L$4:$L$241,"افتراض — يلزم عرض سعر") -> 47530 | H9: =IF(C9=0,0,G9/C9) -> 0.91351144 | I9: =ROUND(C9*'ملخص العرض'!$B$14,2) -> 73754.74
A10: 06 | B10: التكييف والتهوية | C10: =SUMIF('تكسير البنود'!$A$4:$A$241,A10,'تكسير البنود'!$J$4:$J$241) -> 61355 | D10: 71000 | E10: =C10-D10 -> -9645 | F10: =IF(D10=0,0,E10/D10) -> -0.13584507 | G10: =SUMIFS('تكسير البنود'!$J$4:$J$241,'تكسير البنود'!$A$4:$A$241,A10,'تكسير البنود'!$L$4:$L$241,"افتراض — يلزم عرض سعر") -> 25710 | H10: =IF(C10=0,0,G10/C10) -> 0.41903675 | I10: =ROUND(C10*'ملخص العرض'!$B$14,2) -> 86973.33
A11: 07 | B11: السباكة والمياه | C11: =SUMIF('تكسير البنود'!$A$4:$A$241,A11,'تكسير البنود'!$J$4:$J$241) -> 29025.164 | D11: 41000 | E11: =C11-D11 -> -11974.836 | F11: =IF(D11=0,0,E11/D11) -> -0.29206918 | G11: =SUMIFS('تكسير البنود'!$J$4:$J$241,'تكسير البنود'!$A$4:$A$241,A11,'تكسير البنود'!$L$4:$L$241,"افتراض — يلزم عرض سعر") -> 20848.75 | H11: =IF(C11=0,0,G11/C11) -> 0.71829913 | I11: =ROUND(C11*'ملخص العرض'!$B$14,2) -> 41144.41
A12: 08 | B12: الكهرباء العامة | C12: =SUMIF('تكسير البنود'!$A$4:$A$241,A12,'تكسير البنود'!$J$4:$J$241) -> 39840 | D12: 47000 | E12: =C12-D12 -> -7160 | F12: =IF(D12=0,0,E12/D12) -> -0.15234043 | G12: =SUMIFS('تكسير البنود'!$J$4:$J$241,'تكسير البنود'!$A$4:$A$241,A12,'تكسير البنود'!$L$4:$L$241,"افتراض — يلزم عرض سعر") -> 39840 | H12: =IF(C12=0,0,G12/C12) -> 1 | I12: =ROUND(C12*'ملخص العرض'!$B$14,2) -> 56474.9
A13: 09 | B13: المولد الصامت | C13: =SUMIF('تكسير البنود'!$A$4:$A$241,A13,'تكسير البنود'!$J$4:$J$241) -> 24350.281 | D13: 21000 | E13: =C13-D13 -> 3350.2812 | F13: =IF(D13=0,0,E13/D13) -> 0.1595372 | G13: =SUMIFS('تكسير البنود'!$J$4:$J$241,'تكسير البنود'!$A$4:$A$241,A13,'تكسير البنود'!$L$4:$L$241,"افتراض — يلزم عرض سعر") -> 8780 | H13: =IF(C13=0,0,G13/C13) -> 0.36057078 | I13: =ROUND(C13*'ملخص العرض'!$B$14,2) -> 34517.56
A14: 10 | B14: التخزين والتحويل (انفرتر وبطاريات) | C14: =SUMIF('تكسير البنود'!$A$4:$A$241,A14,'تكسير البنود'!$J$4:$J$241) -> 66334.994 | D14: 74000 | E14: =C14-D14 -> -7665.0056 | F14: =IF(D14=0,0,E14/D14) -> -0.10358116 | G14: =SUMIFS('تكسير البنود'!$J$4:$J$241,'تكسير البنود'!$A$4:$A$241,A14,'تكسير البنود'!$L$4:$L$241,"افتراض — يلزم عرض سعر") -> 10830 | H14: =IF(C14=0,0,G14/C14) -> 0.16326224 | I14: =ROUND(C14*'ملخص العرض'!$B$14,2) -> 94032.68
A15: 11 | B15: النظام الشمسي | C15: =SUMIF('تكسير البنود'!$A$4:$A$241,A15,'تكسير البنود'!$J$4:$J$241) -> 20810.043 | D15: 28560 | E15: =C15-D15 -> -7749.957 | F15: =IF(D15=0,0,E15/D15) -> -0.27135704 | G15: =SUMIFS('تكسير البنود'!$J$4:$J$241,'تكسير البنود'!$A$4:$A$241,A15,'تكسير البنود'!$L$4:$L$241,"افتراض — يلزم عرض سعر") -> 15868.125 | H15: =IF(C15=0,0,G15/C15) -> 0.76252245 | I15: =ROUND(C15*'ملخص العرض'!$B$14,2) -> 29499.12
A16: 12 | B16: UPS | C16: =SUMIF('تكسير البنود'!$A$4:$A$241,A16,'تكسير البنود'!$J$4:$J$241) -> 8087.33 | D16: 6500 | E16: =C16-D16 -> 1587.33 | F16: =IF(D16=0,0,E16/D16) -> 0.24420462 | G16: =SUMIFS('تكسير البنود'!$J$4:$J$241,'تكسير البنود'!$A$4:$A$241,A16,'تكسير البنود'!$L$4:$L$241,"افتراض — يلزم عرض سعر") -> 3500 | H16: =IF(C16=0,0,G16/C16) -> 0.43277571 | I16: =ROUND(C16*'ملخص العرض'!$B$14,2) -> 11464.13
... A22: 18 | B22: التصميم والاعتمادات والاختبارات والنقل | C22: =SUMIF('تكسير البنود'!$A$4:$A$241,A22,'تكسير البنود'!$J$4:$J$241) -> 23700 | D22: 32000 | E22: =C22-D22 -> -8300 | F22: =IF(D22=0,0,E22/D22) -> -0.259375 | G22: =SUMIFS('تكسير البنود'!$J$4:$J$241,'تكسير البنود'!$A$4:$A$241,A22,'تكسير البنود'!$L$4:$L$241,"افتراض — يلزم عرض سعر") -> 22500 | H22: =IF(C22=0,0,G22/C22) -> 0.94936709 | I22: =ROUND(C22*'ملخص العرض'!$B$14,2) -> 33595.76
B23: الإجمالي | C23: =SUM(C5:C22) -> 830892.6 | D23: =SUM(D5:D22) -> 928060 | E23: =SUM(E5:E22) -> -97167.404 | F23: =IF(D23=0,0,E23/D23) -> -0.10469948 | G23: =SUM(G5:G22) -> 539378.12 | H23: =IF(C23=0,0,G23/C23) -> 0.64915505 | I23: =SUM(I5:I22) -> 1177825.7
B24: ضريبة القيمة المضافة | I24: =I23*المدخلات!$B$23 -> 176673.85
B25: الإجمالي شامل الضريبة | I25: =I23+I24 -> 1354499.5
B26: فرق التقريب عن الملخص | I26: =I23-'ملخص العرض'!B13 -> 0.013880125

Sheet المدخلات
A1: المدخلات والافتراضات — فرع خدمة العملاء المتنقل
A2: الخلايا الزرقاء مدخلات تُعدَّل، والصفراء افتراضات رئيسية. كل الأسعار قبل ضريبة القيمة المضافة. تاريخ مراجعة الأسعار: 21/10/2026.
A3: البند | B3: القيمة | C3: ملاحظة / المصدر
A4: SAR | B4: 1 | C4: الريال السعودي
A5: USD | B5: 3.75 | C5: سعر الربط الرسمي
A6: EUR | B6: 4.35 | C6: افتراض — يُحدَّث بسعر يوم التسعير
A7: GBP | B7: 5.05 | C7: افتراض — يُحدَّث بسعر يوم التسعير
A8: AED | B8: =3.75/3.6725 -> 1.0211028 | C8: مشتق من ربط الريال والدرهم بالدولار
A9: AUD | B9: 2.45 | C9: افتراض — يُحدَّث بسعر يوم التسعير
A11: معامل تكلفة الاستيراد (شحن + جمارك 5% + تخليص وتأمين) | B11: 1.15 | C11: افتراض: شحن ≈ 6% + رسوم جمركية 5% + تخليص وتأمين ونقل داخلي ≈ 4%
A13: تكلفة يوم العامل الماهر (شاملة السكن والمقابل المالي والتأمينات) | B13: 380 | C13: افتراض: راتب لحام/فني 6,000–12,000 ر.س شهرياً (Paylab) + تكاليف نظامية ÷ 26 يوم عمل
A14: تكلفة يوم العامل المساعد | B14: 250 | C14: افتراض
A16: مدة المشروع (أشهر) | B16: 3 | C16: التسليم خلال 90 يوماً
A18: المصاريف العامة للشركة (من تكلفة المشروع) | B18: 0.05
A19: تكلفة التمويل (من تكلفة المشروع) | B19: 0.025 | C19: بافتراض عدم وجود دفعة مقدمة؛ يُخفَّض إن نصت الكراسة عليها
A20: الضمانات البنكية والتأمين (من تكلفة المشروع) | B20: 0.01
A21: المخاطر والطوارئ (من تكلفة المشروع) | B21: 0.05
A22: الربح (من إجمالي التكلفة) | B22: 0.1
A23: ضريبة القيمة المضافة | B23: 0.15
A25: مستويات الثقة في الأسعار
A26: مصدر سعودي | C26: سعر من متجر أو جهة سعودية
A27: مصدر دولي + استيراد | C27: سعر من متجر دولي + معامل الاستيراد
A28: تقدير بين مصادر | C28: تقدير مبني على أكثر من مصدر أو منتج مقارب
A29: افتراض — يلزم عرض سعر | C29: تقدير هندسي — يجب استبداله بعرض سعر مورد

Sheet تكسير البنود
A1: تكسير البنود — التكلفة المباشرة (قبل الضريبة)
A3: البند | B3: م | C3: الوصف | D3: الوحدة | E3: الكمية | F3: سعر الوحدة (بالعملة) | G3: العملة | H3: مستورد؟ | I3: سعر الوحدة (ر.س) | J3: الإجمالي (ر.س) | K3: النوع | L3: مستوى الثقة | M3: الأساس | N3: الرابط
C4: البند 01 — شاسيه سيمي تريلر منخفض 12 م
A5: 01 | B5: 1 | C5: حديد S355 للكمرات المركبة والعرضيات والسكك والرقبة والصدام (2.93 طن + 5% هالك) | D5: طن | E5: 3.3 | F5: 4200 | G5: ر.س | H5: لا | I5: =F5*VLOOKUP(IF(G5="ر.س","SAR",G5),المدخلات!$A$4:$B$9,2,FALSE())*IF(H5="نعم",المدخلات!$B$11,1) -> 4200 | J5: =E5*I5 -> 13860 | K5: مواد/معدات | L5: افتراض — يلزم عرض سعر | M5: سعر حديد التسليح 2,260 ر.س/طن (حديد، فبراير 2026) + علاوة المقاطع والألواح الإنشائية | N5: https://new.aisusteel.org/archives/3349
A6: 01 | B6: 2 | C6: تصنيع ولحام الشاسيه (3 لحامين × 12 يوم) | D6: يوم | E6: 36 | F6: =المدخلات!$B$13 -> 380 | G6: ر.س | H6: لا | I6: =F6*VLOOKUP(IF(G6="ر.س","SAR",G6),المدخلات!$A$4:$B$9,2,FALSE())*IF(H6="نعم",المدخلات!$B$11,1) -> 380 | J6: =E6*I6 -> 13680 | K6: عمالة | L6: افتراض — يلزم عرض سعر | M6: معدل العمالة من ورقة المدخلات | N6: https://saudiarabia.paylab.com/salaryinfo/mechanical-engineering/welder
A7: 01 | B7: 3 | C7: عمالة مساعدة للشاسيه | D7: يوم | E7: 12 | F7: =المدخلات!$B$14 -> 250 | G7: ر.س | H7: لا | I7: =F7*VLOOKUP(IF(G7="ر.س","SAR",G7),المدخلات!$A$4:$B$9,2,FALSE())*IF(H7="نعم",المدخلات!$B$11,1) -> 250 | J7: =E7*I7 -> 3000 | K7: عمالة | L7: افتراض — يلزم عرض سعر | M7: معدل العمالة من ورقة المدخلات | N7: https://saudiarabia.paylab.com/salaryinfo/mechanical-engineering/welder
A8: 01 | B8: 4 | C8: محور 9 طن بفرامل قرصية | D8: عدد | E8: 2 | F8: 1800 | G8: USD | H8: نعم | I8: =F8*VLOOKUP(IF(G8="ر.س","SAR",G8),المدخلات!$A$4:$B$9,2,FALSE())*IF(H8="نعم",المدخلات!$B$11,1) -> 7762.5 | J8: =E8*I8 -> 15525 | K8: مواد/معدات | L8: افتراض — يلزم عرض سعر | M8: لم يُعثر على سعر منشور — يلزم عرض مصنّع محاور
A9: 01 | B9: 5 | C9: تعليق هوائي ثنائي المحور كامل | D9: طقم | E9: 1 | F9: 1500 | G9: USD | H9: نعم | I9: =F9*VLOOKUP(IF(G9="ر.س","SAR",G9),المدخلات!$A$4:$B$9,2,FALSE())*IF(H9="نعم",المدخلات!$B$11,1) -> 6468.75 | J9: =E9*I9 -> 6468.75 | K9: مواد/معدات | L9: افتراض — يلزم عرض سعر | M9: لم يُعثر على سعر منشور
A10: 01 | B10: 6 | C10: منظومة فرامل EBS/ABS وخزانات هواء | D10: طقم | E10: 1 | F10: 1200 | G10: USD | H10: نعم | I10: =F10*VLOOKUP(IF(G10="ر.س","SAR",G10),المدخلات!$A$4:$B$9,2,FALSE())*IF(H10="نعم",المدخلات!$B$11,1) -> 5175 | J10: =E10*I10 -> 5175 | K10: مواد/معدات | L10: افتراض — يلزم عرض سعر | M10: لم يُعثر على سعر منشور
A11: 01 | B11: 7 | C11: إطار 385/55R19.5 (4 + احتياطي) | D11: عدد | E11: 5 | F11: 1300 | G11: ر.س | H11: لا | I11: =F11*VLOOKUP(IF(G11="ر.س","SAR",G11),المدخلات!$A$4:$B$9,2,FALSE())*IF(H11="نعم",المدخلات!$B$11,1) -> 1300 | J11: =E11*I11 -> 6500 | K11: مواد/معدات | L11: افتراض — يلزم عرض سعر | M11: لم يُعثر على سعر سعودي لهذا المقاس
A12: 01 | B12: 8 | C12: جنط 19.5 | D12: عدد | E12: 5 | F12: 450 | G12: ر.س | H12: لا | I12: =F12*VLOOKUP(IF(G12="ر.س","SAR",G12),المدخلات!$A$4:$B$9,2,FALSE())*IF(H12="نعم",المدخلات!$B$11,1) -> 450 | J12: =E12*I12 -> 2250 | K12: مواد/معدات | L12: افتراض — يلزم عرض سعر | M12: تقدير
A13: 01 | B13: 9 | C13: أرجل هبوط JOST طقم | D13: طقم | E13: 1 | F13: 1400 | G13: USD | H13: نعم | I13: =F13*VLOOKUP(IF(G13="ر.س","SAR",G13),المدخلات!$A$4:$B$9,2,FALSE())*IF(H13="نعم",المدخلات!$B$11,1) -> 6037.5 | J13: =E13*I13 -> 6037.5 | K13: مواد/معدات | L13: مصدر دولي + استيراد | M13: JOST A400 طقم كامل | N13: https://semitrailers.net/shop/jost-complete-landing-gear-set-model-a400-g-19/
A14: 01 | B14: 10 | C14: أرجل تثبيت 10 طن بأذرع منزلقة | D14: عدد | E14: 4 | F14: 2500 | G14: ر.س | H14: لا | I14: =F14*VLOOKUP(IF(G14="ر.س","SAR",G14),المدخلات!$A$4:$B$9,2,FALSE())*IF(H14="نعم",المدخلات!$B$11,1) -> 2500 | J14: =E14*I14 -> 10000 | K14: مواد/معدات | L14: افتراض — يلزم عرض سعر | M14: لم يُعثر على سعر منشور
A15: 01 | B15: 11 | C15: كنج بن ISO 337 + لوح تقوية | D15: طقم | E15: 1 | F15: 1200 | G15: ر.س | H15: لا | I15: =F15*VLOOKUP(IF(G15="ر.س","SAR",G15),المدخلات!$A$4:$B$9,2,FALSE())*IF(H15="نعم",المدخلات!$B$11,1) -> 1200 | J15: =E15*I15 -> 1200 | K15: مواد/معدات | L15: افتراض — يلزم عرض سعر | M15: تقدير
A16: 01 | B16: 12 | C16: إنارة طريق 24V وتمديدات ISO 1185 ورفارف وحواجز SASO | D16: طقم | E16: 1 | F16: 4500 | G16: ر.س | H16: لا | I16: =F16*VLOOKUP(IF(G16="ر.س","SAR",G16),المدخلات!$A$4:$B$9,2,FALSE())*IF(H16="نعم",المدخلات!$B$11,1) -> 4500 | J16: =E16*I16 -> 4500 | K16: مواد/معدات | L16: افتراض — يلزم عرض سعر | M16: تقدير
A17: 01 | B17: 13 | C17: صناديق تخزين سفلية | D17: عدد | E17: 4 | F17: 1200 | G17: ر.س | H17: لا | I17: =F17*VLOOKUP(IF(G17="ر.س","SAR",G17),المدخلات!$A$4:$B$9,2,FALSE())*IF(H17="نعم",المدخلات!$B$11,1) -> 1200 | J17: =E17*I17 -> 4800 | K17: مواد/معدات | L17: افتراض — يلزم عرض سعر | M17: تقدير
A18: 01 | B18: 14 | C18: سفع رملي ودهان أساس ونهائي للشاسيه | D18: مقطوع | E18: 1 | F18: 4000 | G18: ر.س | H18: لا | I18: =F18*VLOOKUP(IF(G18="ر.س","SAR",G18),المدخلات!$A$4:$B$9,2,FALSE())*IF(H18="نعم",المدخلات!$B$11,1) -> 4000 | J18: =E18*I18 -> 4000 | K18: مقاول باطن/خدمة | L18: افتراض — يلزم عرض سعر | M18: تقدير
C19: إجمالي البند 01 | J19: =SUMIF($A$4:$A$18,"01",$J$4:$J$18) -> 96996.25
C21: البند 02 — هيكل الصندوق والعزل والأرضية
A22: 02 | B22: 1 | C22: مواسير RHS 80×40×3 للجدران وأقواس السقف (1.29 طن + 5%) | D22: طن | E22: 1.35 | F22: 4200 | G22: ر.س | H22: لا | I22: =F22*VLOOKUP(IF(G22="ر.س","SAR",G22),المدخلات!$A$4:$B$9,2,FALSE())*IF(H22="نعم",المدخلات!$B$11,1) -> 4200 | J22: =E22*I22 -> 5670 | K22: مواد/معدات | L22: افتراض — يلزم عرض سعر | M22: كالبند 01 | N22: https://new.aisusteel.org/archives/3349
A23: 02 | B23: 2 | C23: ساندوتش بانل صوف صخري 100 مم للجدران والسقف (91 م² + 8%) | D23: م² | E23: 98 | F23: 140 | G23: ر.س | H23: لا | I23: =F23*VLOOKUP(IF(G23="ر.س","SAR",G23),المدخلات!$A$4:$B$9,2,FALSE())*IF(H23="نعم",المدخلات!$B$11,1) -> 140 | J23: =E23*I23 -> 13720 | K23: مواد/معدات | L23: تقدير بين مصادر | M23: نطاق 100–180 ر.س/م² في السعودية؛ 16–18 دولار FOB من الصين | N23: https://www.alibaba.com/product-insights/sandwich-panel-price-in-saudi.html
A24: 02 | B24: 3 | C24: عزل صوف صخري إضافي 40–50 مم (إطار السقف + الأرضية) | D24: م² | E24: 60 | F24: 30 | G24: ر.س | H24: لا | I24: =F24*VLOOKUP(IF(G24="ر.س","SAR",G24),المدخلات!$A$4:$B$9,2,FALSE())*IF(H24="نعم",المدخلات!$B$11,1) -> 30 | J24: =E24*I24 -> 1800 | K24: مواد/معدات | L24: مصدر سعودي | M24: ألواح صوف صخري سعودية 50 مم — مدار | N24: https://www.madar.com/en_SA/rockwool-slab-50-x-600-x-1200mm-100kg-m3.html
A25: 02 | B25: 4 | C25: صاج مجلفن 2 مم للأرضية السفلية (471 كجم) | D25: طن | E25: 0.5 | F25: 5000 | G25: ر.س | H25: لا | I25: =F25*VLOOKUP(IF(G25="ر.س","SAR",G25),المدخلات!$A$4:$B$9,2,FALSE())*IF(H25="نعم",المدخلات!$B$11,1) -> 5000 | J25: =E25*I25 -> 2500 | K25: مواد/معدات | L25: افتراض — يلزم عرض سعر | M25: تقدير
A26: 02 | B26: 5 | C26: بلاي وود بحري 18 مم (لوح 2.98 م²) | D26: لوح | E26: 11 | F26: 220 | G26: ر.س | H26: لا | I26: =F26*VLOOKUP(IF(G26="ر.س","SAR",G26),المدخلات!$A$4:$B$9,2,FALSE())*IF(H26="نعم",المدخلات!$B$11,1) -> 220 | J26: =E26*I26 -> 2420 | K26: مواد/معدات | L26: افتراض — يلزم عرض سعر | M26: لم يُعثر على سعر سعودي منشور
A27: 02 | B27: 6 | C27: جدار حريق EI60 + جدار حجرة المولد | D27: م² | E27: 8 | F27: 450 | G27: ر.س | H27: لا | I27: =F27*VLOOKUP(IF(G27="ر.س","SAR",G27),المدخلات!$A$4:$B$9,2,FALSE())*IF(H27="نعم",المدخلات!$B$11,1) -> 450 | J27: =E27*I27 -> 3600 | K27: مواد/معدات | L27: افتراض — يلزم عرض سعر | M27: تقدير
A28: 02 | B28: 7 | C28: قواطع داخلية 80 مم (الحمام، السيرفر، الممر) | D28: م² | E28: 18 | F28: 220 | G28: ر.س | H28: لا | I28: =F28*VLOOKUP(IF(G28="ر.س","SAR",G28),المدخلات!$A$4:$B$9,2,FALSE())*IF(H28="نعم",المدخلات!$B$11,1) -> 220 | J28: =E28*I28 -> 3960 | K28: مواد/معدات | L28: افتراض — يلزم عرض سعر | M28: تقدير
A29: 02 | B29: 8 | C29: طلاء سقف عاكس SRI ≥ 78 | D29: م² | E29: 30 | F29: 60 | G29: ر.س | H29: لا | I29: =F29*VLOOKUP(IF(G29="ر.س","SAR",G29),المدخلات!$A$4:$B$9,2,FALSE())*IF(H29="نعم",المدخلات!$B$11,1) -> 60 | J29: =E29*I29 -> 1800 | K29: مواد/معدات | L29: افتراض — يلزم عرض سعر | M29: تقدير
A30: 02 | B30: 9 | C30: دهان خارجي أبيض عاكس | D30: م² | E30: 70 | F30: 45 | G30: ر.س | H30: لا | I30: =F30*VLOOKUP(IF(G30="ر.س","SAR",G30),المدخلات!$A$4:$B$9,2,FALSE())*IF(H30="نعم",المدخلات!$B$11,1) -> 45 | J30: =E30*I30 -> 3150 | K30: مواد/معدات | L30: افتراض — يلزم عرض سعر | M30: تقدير
A31: 02 | B31: 10 | C31: إيبوكسي وفيبرجلاس أسفل الأرضية | D31: م² | E31: 30 | F31: 110 | G31: ر.س | H31: لا | I31: =F31*VLOOKUP(IF(G31="ر.س","SAR",G31),المدخلات!$A$4:$B$9,2,FALSE())*IF(H31="نعم",المدخلات!$B$11,1) -> 110 | J31: =E31*I31 -> 3300 | K31: مواد/معدات | L31: افتراض — يلزم عرض سعر | M31: تقدير
A32: 02 | B32: 11 | C32: مانعات تسرب وEPDM وقواطع حرارية ومثبتات | D32: مقطوع | E32: 1 | F32: 3500 | G32: ر.س | H32: لا | I32: =F32*VLOOKUP(IF(G32="ر.س","SAR",G32),المدخلات!$A$4:$B$9,2,FALSE())*IF(H32="نعم",المدخلات!$B$11,1) -> 3500 | J32: =E32*I32 -> 3500 | K32: مواد/معدات | L32: افتراض — يلزم عرض سعر | M32: تقدير
A33: 02 | B33: 12 | C33: تصنيع وتجميع الصندوق (4 فنيين × 25 يوم) | D33: يوم | E33: 100 | F33: =المدخلات!$B$13 -> 380 | G33: ر.س | H33: لا | I33: =F33*VLOOKUP(IF(G33="ر.س","SAR",G33),المدخلات!$A$4:$B$9,2,FALSE())*IF(H33="نعم",المدخلات!$B$11,1) -> 380 | J33: =E33*I33 -> 38000 | K33: عمالة | L33: افتراض — يلزم عرض سعر | M33: معدل العمالة من المدخلات | N33: https://saudiarabia.paylab.com/salaryinfo/mechanical-engineering/welder
A34: 02 | B34: 13 | C34: عمالة مساعدة للصندوق | D34: يوم | E34: 50 | F34: =المدخلات!$B$14 -> 250 | G34: ر.س | H34: لا | I34: =F34*VLOOKUP(IF(G34="ر.س","SAR",G34),المدخلات!$A$4:$B$9,2,FALSE())*IF(H34="نعم",المدخلات!$B$11,1) -> 250 | J34: =E34*I34 -> 12500 | K34: عمالة | L34: افتراض — يلزم عرض سعر | M34: معدل العمالة من المدخلات | N34: https://saudiarabia.paylab.com/salaryinfo/mechanical-engineering/welder
C35: إجمالي البند 02 | J35: =SUMIF($A$4:$A$34,"02",$J$4:$J$34) -> 95920
C37: البند 03 — الأبواب والنوافذ
A38: 03 | B38: 1 | C38: D-01 باب ألمنيوم معزول ثقيل 1.10×2.10 بزجاج وPanic bar | D38: عدد | E38: 1 | F38: 6500 | G38: ر.س | H38: لا | I38: =F38*VLOOKUP(IF(G38="ر.س","SAR",G38),المدخلات!$A$4:$B$9,2,FALSE())*IF(H38="نعم",المدخلات!$B$11,1) -> 6500 | J38: =E38*I38 -> 6500 | K38: مواد/معدات | L38: افتراض — يلزم عرض سعر | M38: تقدير
A39: 03 | B39: 2 | C39: D-02 باب ألمنيوم معزول 1.00×2.10 بPanic bar | D39: عدد | E39: 1 | F39: 6000 | G39: ر.س | H39: لا | I39: =F39*VLOOKUP(IF(G39="ر.س","SAR",G39),المدخلات!$A$4:$B$9,2,FALSE())*IF(H39="نعم",المدخلات!$B$11,1) -> 6000 | J39: =E39*I39 -> 6000 | K39: مواد/معدات | L39: افتراض — يلزم عرض سعر | M39: تقدير
A40: 03 | B40: 3 | C40: D-03 باب مولد مزدوج بشرائح وبطانة صوتية | D40: عدد | E40: 1 | F40: 4500 | G40: ر.س | H40: لا | I40: =F40*VLOOKUP(IF(G40="ر.س","SAR",G40),المدخلات!$A$4:$B$9,2,FALSE())*IF(H40="نعم",المدخلات!$B$11,1) -> 4500 | J40: =E40*I40 -> 4500 | K40: مواد/معدات | L40: افتراض — يلزم عرض سعر | M40: تقدير
A41: 03 | B41: 4 | C41: D-04 باب فولاذي EI60 | D41: عدد | E41: 1 | F41: 3800 | G41: ر.س | H41: لا | I41: =F41*VLOOKUP(IF(G41="ر.س","SAR",G41),المدخلات!$A$4:$B$9,2,FALSE())*IF(H41="نعم",المدخلات!$B$11,1) -> 3800 | J41: =E41*I41 -> 3800 | K41: مواد/معدات | L41: افتراض — يلزم عرض سعر | M41: تقدير
A42: 03 | B42: 5 | C42: D-05/D-06 أبواب WPC مقاومة للماء | D42: عدد | E42: 2 | F42: 1400 | G42: ر.س | H42: لا | I42: =F42*VLOOKUP(IF(G42="ر.س","SAR",G42),المدخلات!$A$4:$B$9,2,FALSE())*IF(H42="نعم",المدخلات!$B$11,1) -> 1400 | J42: =E42*I42 -> 2800 | K42: مواد/معدات | L42: افتراض — يلزم عرض سعر | M42: تقدير
A43: 03 | B43: 6 | C43: نظام أقفال متداخلة لبابي الحمام | D43: طقم | E43: 1 | F43: 1800 | G43: ر.س | H43: لا | I43: =F43*VLOOKUP(IF(G43="ر.س","SAR",G43),المدخلات!$A$4:$B$9,2,FALSE())*IF(H43="نعم",المدخلات!$B$11,1) -> 1800 | J43: =E43*I43 -> 1800 | K43: مواد/معدات | L43: افتراض — يلزم عرض سعر | M43: تقدير
...

Sheet مصاريف المشروع
A1: مصاريف المشروع غير المباشرة
A3: البند | B3: العدد | C3: التكلفة الشهرية (ر.س) | D3: المدة (شهر) | E3: مبلغ مقطوع (ر.س) | F3: الإجمالي (ر.س)
A4: مدير مشروع (نصف دوام) — افتراض | B4: 0.5 | C4: 18000 | D4: =المدخلات!$B$16 -> 3 | F4: =IF(E4<>"",E4,B4*C4*D4) -> 27000
A5: مهندس مشروع/ورشة متفرغ — افتراض | B5: 1 | C5: 12000 | D5: =المدخلات!$B$16 -> 3 | F5: =IF(E5<>"",E5,B5*C5*D5) -> 36000
A6: مراقب جودة وسلامة (نصف دوام) — افتراض | B6: 0.5 | C6: 8000 | D6: =المدخلات!$B$16 -> 3 | F6: =IF(E6<>"",E6,B6*C6*D6) -> 12000
A7: مشتريات ولوجستيات (نصف دوام) — افتراض | B7: 0.5 | C7: 7000 | D7: =المدخلات!$B$16 -> 3 | F7: =IF(E7<>"",E7,B7*C7*D7) -> 10500
A8: حصة الورشة والمرافق والرافعات — افتراض | B8: 1 | C8: 6000 | D8: =المدخلات!$B$16 -> 3 | F8: =IF(E8<>"",E8,B8*C8*D8) -> 18000
A9: تشغيل تجريبي 72 ساعة: وقود ومستهلكات — افتراض | E9: 3000 | F9: =IF(E9<>"",E9,B9*C9*D9) -> 3000
A10: تدريب موظفي العميل وأدلة التشغيل والصيانة — افتراض | E10: 6000 | F10: =IF(E10<>"",E10,B10*C10*D10) -> 6000
A11: الإجمالي | F11: =SUM(F4:F10) -> 112500

Sheet البنود الاختيارية
A1: البنود الاختيارية (خارج إجمالي العرض)
A2: معامل الإضافات = (1 + عامة + تمويل + ضمانات + طوارئ) × (1 + ربح)، دون مصاريف المشروع لأنها مغطاة في العرض الأساسي.
A3: معامل البنود الاختيارية | B3: =(1+المدخلات!$B$18+المدخلات!$B$19+المدخلات!$B$20+المدخلات!$B$21)*(1+المدخلات!$B$22) -> 1.2485
A5: البند | B5: الوصف | C5: الوحدة | D5: التكلفة المباشرة (ر.س) | E5: السعر في العرض (ر.س) | F5: الأساس
A6: خ-1 | B6: استبدال المولد بمولد صامت 10 ك.ف.أ (الفرق فقط) | C6: مقطوع | D6: =(4800-3112.5)*VLOOKUP("EUR",المدخلات!$A$4:$B$9,2,FALSE())*المدخلات!$B$11+2500 -> 10941.719 | E6: =ROUND(D6*$B$3,0) -> 13661 | F6: مولد 10 ك.ف.أ من الفئة نفسها ≈ 4,800 يورو (افتراض) ناقص المولد الأساسي 3,112.50 يورو، + 2,500 ر.س تعديل الحجرة والكابلات
A7: خ-2 | B7: مكيف سقفي RV انفرتر إضافي لمنطقة الموظفين | C7: عدد | D7: =(1900+250)*VLOOKUP("USD",المدخلات!$A$4:$B$9,2,FALSE())*المدخلات!$B$11+2*المدخلات!$B$13+600 -> 10631.875 | E7: =ROUND(D7*$B$3,0) -> 13274 | F7: سعر المكيف وصندوق التوزيع نفسه في البند 06 + يوما تركيب + 600 ر.س تمديدات وقاطع
A8: خ-3 | B8: عزل حراري للأرضية | C8: — | D8: 0 | E8: =ROUND(D8*$B$3,0) -> 0 | F8: مشمول في البند 02 (صوف صخري 50 مم)
A9: خ-4أ | B9: لابتوب Dell Latitude 5450 Ultra 7 16/512 مع التهيئة | C9: عدد | D9: =4296+150 -> 4446 | E9: =ROUND(D9*$B$3,0) -> 5551 | F9: ابتكار 4,940 ر.س شامل الضريبة + 150 ر.س تهيئة
A10: خ-4ب | B10: تابلت Samsung Galaxy Tab S11 5G | C10: عدد | D10: =1049/1.2*VLOOKUP("EUR",المدخلات!$A$4:$B$9,2,FALSE()) -> 3802.625 | E10: =ROUND(D10*$B$3,0) -> 4748 | F10: سعر الإطلاق الأوروبي 1,049 يورو شامل ضريبة ≈ 20% — يُؤكد من جرير أو إكسترا
A11: خ-4ج | B11: نقطة وصول Cisco CW9176I مع التركيب والتهيئة (دون تراخيص الاشتراك) | C11: عدد | D11: =1505.37*VLOOKUP("USD",المدخلات!$A$4:$B$9,2,FALSE())*المدخلات!$B$11+300 -> 6791.9081 | E11: =ROUND(D11*$B$3,0) -> 8480 | F11: Hummingbird Networks 1,505.37 دولار + معامل الاستيراد + 300 ر.س تركيب

Sheet المصادر
A1: مصادر الأسعار (تمت مراجعتها في 21/10/2026)
A3: البند | B3: المكوّن | C3: المصدر | D3: الرابط
A4: 01 | B4: حديد S355 للكمرات المركبة والعرضيات والسكك والرقبة والصدام (2.93 طن + 5% هالك) | C4: سعر حديد التسليح 2,260 ر.س/طن (حديد، فبراير 2026) + علاوة المقاطع والألواح الإنشائية | D4: https://new.aisusteel.org/archives/3349
A5: 01 | B5: تصنيع ولحام الشاسيه (3 لحامين × 12 يوم) | C5: معدل العمالة من ورقة المدخلات | D5: https://saudiarabia.paylab.com/salaryinfo/mechanical-engineering/welder
A6: 01 | B6: عمالة مساعدة للشاسيه | C6: معدل العمالة من ورقة المدخلات | D6: https://saudiarabia.paylab.com/salaryinfo/mechanical-engineering/welder
A7: 01 | B7: أرجل هبوط JOST طقم | C7: JOST A400 طقم كامل | D7: https://semitrailers.net/shop/jost-complete-landing-gear-set-model-a400-g-19/
A8: 02 | B8: مواسير RHS 80×40×3 للجدران وأقواس السقف (1.29 طن + 5%) | C8: كالبند 01 | D8: https://new.aisusteel.org/archives/3349
A9: 02 | B9: ساندوتش بانل صوف صخري 100 مم للجدران والسقف (91 م² + 8%) | C9: نطاق 100–180 ر.س/م² في السعودية؛ 16–18 دولار FOB من الصين | D9: https://www.alibaba.com/product-insights/sandwich-panel-price-in-saudi.html
A10: 02 | B10: عزل صوف صخري إضافي 40–50 مم (إطار السقف + الأرضية) | C10: ألواح صوف صخري سعودية 50 مم — مدار | D10: https://www.madar.com/en_SA/rockwool-slab-50-x-600-x-1200mm-100kg-m3.html
A11: 02 | B11: تصنيع وتجميع الصندوق (4 فنيين × 25 يوم) | C11: معدل العمالة من المدخلات | D11: https://saudiarabia.paylab.com/salaryinfo/mechanical-engineering/welder
A12: 02 | B12: عمالة مساعدة للصندوق | C12: معدل العمالة من المدخلات | D12: https://saudiarabia.paylab.com/salaryinfo/mechanical-engineering/welder
A13: 03 | B13: تركيب الأبواب والنوافذ | C13: معدل العمالة من المدخلات | D13: https://saudiarabia.paylab.com/salaryinfo/mechanical-engineering/welder
A14: 04 | B14: مصعد كراسي تحت الأرضية 350 كجم (UVL أو مكافئ) | C14: لا يُنشر سعر UVL؛ مصعد BraunAbility جانبي يبدأ من 6,093 دولار — UVL أعلى | D14: https://www.consumeraffairs.com/automotive/scooter-lifts/
... A61: 18 | B61: تسجيل ولوحات وVIN وفحص فني أولي | C61: رسوم فحص الشاحنة الكبيرة 235.75 ر.س + رخصة سير النقل 200 ر.س | D61: https://ksa.motory.com/ar/%D8%A7%D9%84%D8%A7%D8%AE%D8%A8%D8%A7%D8%B1/%D9%81%D8%AD%D8%B5-%D9%81%D9%86%D9%8A-%D8%AF%D9%88%D8%B1%D9%8A-%D8%B3%D9%8A%D8%A7%D8%B1%D8%A7%D8%AA-%D8%A7%D9%84%D8%B3%D8%B9%D9%88%D8%AF%D9%8A%D8%A9/
A63: ملاحظة: لم تُفتح صفحات المواقع الحكومية والمتاجر مباشرة لأن الشبكة تحجبها؛ الأسعار مأخوذة من نتائج محركات البحث وتُؤكد بعروض موردين قبل التسليم.
